Workbook
Name Slicer_Country: #N/A
Name Slicer_Customer_Age2: #N/A
Name Slicer_Risk_Level: #N/A

Sheet Dashboard

Sheet Transactions
A1: Transaction ID | B1: Amount | C1: Hour of Day | D1: Country | E1: Customer Age2 | F1: Prior High-Risk Transactions | G1: Transaction Date | H1: High-Risk Country | I1: Late Night Flag | J1: Amount Flag | K1: Prior Risk Flag | L1: Risk Score | M1: Risk Level | W1: Customer Age
A2: TXN00001 | B2: 5649.37 | C2: 0 | D2: UK | E2: {=_xlfn.IFS(AND(W2>=18,W2<=25),"18-25",AND(W2>25,W2<=35),"26-35",AND(W2>35,W2<=45),"36-45",AND(W2>45,W2<=55),"46-55",AND(W2>55,W2<=65),"56-65",W2>65,"65+")} -> 46-55 | F2: 6 | G2: 10/21/2025 | H2: =IF(OR(D2="Nigeria",D2="Bangladesh",D2="Pakistan",D2="North Korea",D2="Iran",D2="Syria"),1,0) -> 0 | I2: =IF(AND(C2>=2,C2<=5),1,0) -> 0 | J2: =IF(B2>5000,1,0) -> 1 | K2: =IF(F2>=3,1,0) -> 1 | L2: =IF(AND(B2>5000,C2>=2,C2<=5,H2=1),5,0) + IF(AND(B2>5000,H2=1),3,0) + IF(AND(C2>=2,C2<=5,B2>3000),2,0) + IF(F2>=5,2,0) + IF(AND(W2<25,B2>8000),1,0) + IF(AND(H2=1,B2>3000),2,0) -> 2 | M2: =IF(L2>=10,"CRITICAL",IF(L2>=7,"HIGH",IF(L2>=4,"MEDIUM","LOW"))) -> LOW | W2: 54
A3: TXN00002 | B3: 14263.18 | C3: 0 | D3: Germany | E3: {=_xlfn.IFS(AND(W3>=18,W3<=25),"18-25",AND(W3>25,W3<=35),"26-35",AND(W3>35,W3<=45),"36-45",AND(W3>45,W3<=55),"46-55",AND(W3>55,W3<=65),"56-65",W3>65,"65+")} -> 36-45 | F3: 8 | G3: 10/04/2025 | H3: =IF(OR(D3="Nigeria",D3="Bangladesh",D3="Pakistan",D3="North Korea",D3="Iran",D3="Syria"),1,0) -> 0 | I3: =IF(AND(C3>=2,C3<=5),1,0) -> 0 | J3: =IF(B3>5000,1,0) -> 1 | K3: =IF(F3>=3,1,0) -> 1 | L3: =IF(AND(B3>5000,C3>=2,C3<=5,H3=1),5,0) + IF(AND(B3>5000,H3=1),3,0) + IF(AND(C3>=2,C3<=5,B3>3000),2,0) + IF(F3>=5,2,0) + IF(AND(W3<25,B3>8000),1,0) + IF(AND(H3=1,B3>3000),2,0) -> 2 | M3: =IF(L3>=10,"CRITICAL",IF(L3>=7,"HIGH",IF(L3>=4,"MEDIUM","LOW"))) -> LOW | O3: =COUNTIF(B:B,M2="CRITICAL") -> 0 | W3: 40
A4: TXN00003 | B4: 10993.31 | C4: 18 | D4: Syria | E4: {=_xlfn.IFS(AND(W4>=18,W4<=25),"18-25",AND(W4>25,W4<=35),"26-35",AND(W4>35,W4<=45),"36-45",AND(W4>45,W4<=55),"46-55",AND(W4>55,W4<=65),"56-65",W4>65,"65+")} -> 65+ | F4: 6 | G4: 10/01/2025 | H4: =IF(OR(D4="Nigeria",D4="Bangladesh",D4="Pakistan",D4="North Korea",D4="Iran",D4="Syria"),1,0) -> 1 | I4: =IF(AND(C4>=2,C4<=5),1,0) -> 0 | J4: =IF(B4>5000,1,0) -> 1 | K4: =IF(F4>=3,1,0) -> 1 | L4: =IF(AND(B4>5000,C4>=2,C4<=5,H4=1),5,0) + IF(AND(B4>5000,H4=1),3,0) + IF(AND(C4>=2,C4<=5,B4>3000),2,0) + IF(F4>=5,2,0) + IF(AND(W4<25,B4>8000),1,0) + IF(AND(H4=1,B4>3000),2,0) -> 7 | M4: =IF(L4>=10,"CRITICAL",IF(L4>=7,"HIGH",IF(L4>=4,"MEDIUM","LOW"))) -> HIGH | W4: 75
A5: TXN00004 | B5: 8999.94 | C5: 1 | D5: Germany | E5: {=_xlfn.IFS(AND(W5>=18,W5<=25),"18-25",AND(W5>25,W5<=35),"26-35",AND(W5>35,W5<=45),"36-45",AND(W5>45,W5<=55),"46-55",AND(W5>55,W5<=65),"56-65",W5>65,"65+")} -> 26-35 | F5: 4 | G5: 10/24/2025 | H5: =IF(OR(D5="Nigeria",D5="Bangladesh",D5="Pakistan",D5="North Korea",D5="Iran",D5="Syria"),1,0) -> 0 | I5: =IF(AND(C5>=2,C5<=5),1,0) -> 0 | J5: =IF(B5>5000,1,0) -> 1 | K5: =IF(F5>=3,1,0) -> 1 | L5: =IF(AND(B5>5000,C5>=2,C5<=5,H5=1),5,0) + IF(AND(B5>5000,H5=1),3,0) + IF(AND(C5>=2,C5<=5,B5>3000),2,0) + IF(F5>=5,2,0) + IF(AND(W5<25,B5>8000),1,0) + IF(AND(H5=1,B5>3000),2,0) -> 0 | M5: =IF(L5>=10,"CRITICAL",IF(L5>=7,"HIGH",IF(L5>=4,"MEDIUM","LOW"))) -> LOW | W5: 27
A6: TXN00005 | B6: 2382.48 | C6: 20 | D6: Pakistan | E6: {=_xlfn.IFS(AND(W6>=18,W6<=25),"18-25",AND(W6>25,W6<=35),"26-35",AND(W6>35,W6<=45),"36-45",AND(W6>45,W6<=55),"46-55",AND(W6>55,W6<=65),"56-65",W6>65,"65+")} -> 65+ | F6: 9 | G6: 10/09/2025 | H6: =IF(OR(D6="Nigeria",D6="Bangladesh",D6="Pakistan",D6="North Korea",D6="Iran",D6="Syria"),1,0) -> 1 | I6: =IF(AND(C6>=2,C6<=5),1,0) -> 0 | J6: =IF(B6>5000,1,0) -> 0 | K6: =IF(F6>=3,1,0) -> 1 | L6: =IF(AND(B6>5000,C6>=2,C6<=5,H6=1),5,0) + IF(AND(B6>5000,H6=1),3,0) + IF(AND(C6>=2,C6<=5,B6>3000),2,0) + IF(F6>=5,2,0) + IF(AND(W6<25,B6>8000),1,0) + IF(AND(H6=1,B6>3000),2,0) -> 2 | M6: =IF(L6>=10,"CRITICAL",IF(L6>=7,"HIGH",IF(L6>=4,"MEDIUM","LOW"))) -> LOW | W6: 71
A7: TXN00006 | B7: 2382.12 | C7: 11 | D7: Canada | E7: {=_xlfn.IFS(AND(W7>=18,W7<=25),"18-25",AND(W7>25,W7<=35),"26-35",AND(W7>35,W7<=45),"36-45",AND(W7>45,W7<=55),"46-55",AND(W7>55,W7<=65),"56-65",W7>65,"65+")} -> 18-25 | F7: 9 | G7: 10/08/2025 | H7: =IF(OR(D7="Nigeria",D7="Bangladesh",D7="Pakistan",D7="North Korea",D7="Iran",D7="Syria"),1,0) -> 0 | I7: =IF(AND(C7>=2,C7<=5),1,0) -> 0 | J7: =IF(B7>5000,1,0) -> 0 | K7: =IF(F7>=3,1,0) -> 1 | L7: =IF(AND(B7>5000,C7>=2,C7<=5,H7=1),5,0) + IF(AND(B7>5000,H7=1),3,0) + IF(AND(C7>=2,C7<=5,B7>3000),2,0) + IF(F7>=5,2,0) + IF(AND(W7<25,B7>8000),1,0) + IF(AND(H7=1,B7>3000),2,0) -> 2 | M7: =IF(L7>=10,"CRITICAL",IF(L7>=7,"HIGH",IF(L7>=4,"MEDIUM","LOW"))) -> LOW | W7: 22
A8: TXN00007 | B8: 918.35 | C8: 5 | D8: Netherlands | E8: {=_xlfn.IFS(AND(W8>=18,W8<=25),"18-25",AND(W8>25,W8<=35),"26-35",AND(W8>35,W8<=45),"36-45",AND(W8>45,W8<=55),"46-55",AND(W8>55,W8<=65),"56-65",W8>65,"65+")} -> 46-55 | F8: 6 | G8: 10/08/2025 | H8: =IF(OR(D8="Nigeria",D8="Bangladesh",D8="Pakistan",D8="North Korea",D8="Iran",D8="Syria"),1,0) -> 0 | I8: =IF(AND(C8>=2,C8<=5),1,0) -> 1 | J8: =IF(B8>5000,1,0) -> 0 | K8: =IF(F8>=3,1,0) -> 1 | L8: =IF(AND(B8>5000,C8>=2,C8<=5,H8=1),5,0) + IF(AND(B8>5000,H8=1),3,0) + IF(AND(C8>=2,C8<=5,B8>3000),2,0) + IF(F8>=5,2,0) + IF(AND(W8<25,B8>8000),1,0) + IF(AND(H8=1,B8>3000),2,0) -> 2 | M8: =IF(L8>=10,"CRITICAL",IF(L8>=7,"HIGH",IF(L8>=4,"MEDIUM","LOW"))) -> LOW | W8: 53
A9: TXN00008 | B9: 12999.33 | C9: 22 | D9: Canada | E9: {=_xlfn.IFS(AND(W9>=18,W9<=25),"18-25",AND(W9>25,W9<=35),"26-35",AND(W9>35,W9<=45),"36-45",AND(W9>45,W9<=55),"46-55",AND(W9>55,W9<=65),"56-65",W9>65,"65+")} -> 46-55 | F9: 9 | G9: 10/05/2025 | H9: =IF(OR(D9="Nigeria",D9="Bangladesh",D9="Pakistan",D9="North Korea",D9="Iran",D9="Syria"),1,0) -> 0 | I9: =IF(AND(C9>=2,C9<=5),1,0) -> 0 | J9: =IF(B9>5000,1,0) -> 1 | K9: =IF(F9>=3,1,0) -> 1 | L9: =IF(AND(B9>5000,C9>=2,C9<=5,H9=1),5,0) + IF(AND(B9>5000,H9=1),3,0) + IF(AND(C9>=2,C9<=5,B9>3000),2,0) + IF(F9>=5,2,0) + IF(AND(W9<25,B9>8000),1,0) + IF(AND(H9=1,B9>3000),2,0) -> 2 | M9: =IF(L9>=10,"CRITICAL",IF(L9>=7,"HIGH",IF(L9>=4,"MEDIUM","LOW"))) -> LOW | W9: 51
A10: TXN00009 | B10: 9036.67 | C10: 3 | D10: Bangladesh | E10: {=_xlfn.IFS(AND(W10>=18,W10<=25),"18-25",AND(W10>25,W10<=35),"26-35",AND(W10>35,W10<=45),"36-45",AND(W10>45,W10<=55),"46-55",AND(W10>55,W10<=65),"56-65",W10>65,"65+")} -> 65+ | F10: 4 | G10: 10/24/2025 | H10: =IF(OR(D10="Nigeria",D10="Bangladesh",D10="Pakistan",D10="North Korea",D10="Iran",D10="Syria"),1,0) -> 1 | I10: =IF(AND(C10>=2,C10<=5),1,0) -> 1 | J10: =IF(B10>5000,1,0) -> 1 | K10: =IF(F10>=3,1,0) -> 1 | L10: =IF(AND(B10>5000,C10>=2,C10<=5,H10=1),5,0) + IF(AND(B10>5000,H10=1),3,0) + IF(AND(C10>=2,C10<=5,B10>3000),2,0) + IF(F10>=5,2,0) + IF(AND(W10<25,B10>8000),1,0) + IF(AND(H10=1,B10>3000),2,0) -> 12 | M10: =IF(L10>=10,"CRITICAL",IF(L10>=7,"HIGH",IF(L10>=4,"MEDIUM","LOW"))) -> CRITICAL | W10: 69
A11: TXN00010 | B11: 10635.69 | C11: 22 | D11: Syria | E11: {=_xlfn.IFS(AND(W11>=18,W11<=25),"18-25",AND(W11>25,W11<=35),"26-35",AND(W11>35,W11<=45),"36-45",AND(W11>45,W11<=55),"46-55",AND(W11>55,W11<=65),"56-65",W11>65,"65+")} -> 46-55 | F11: 2 | G11: 10/04/2025 | H11: =IF(OR(D11="Nigeria",D11="Bangladesh",D11="Pakistan",D11="North Korea",D11="Iran",D11="Syria"),1,0) -> 1 | I11: =IF(AND(C11>=2,C11<=5),1,0) -> 0 | J11: =IF(B11>5000,1,0) -> 1 | K11: =IF(F11>=3,1,0) -> 0 | L11: =IF(AND(B11>5000,C11>=2,C11<=5,H11=1),5,0) + IF(AND(B11>5000,H11=1),3,0) + IF(AND(C11>=2,C11<=5,B11>3000),2,0) + IF(F11>=5,2,0) + IF(AND(W11<25,B11>8000),1,0) + IF(AND(H11=1,B11>3000),2,0) -> 5 | M11: =IF(L11>=10,"CRITICAL",IF(L11>=7,"HIGH",IF(L11>=4,"MEDIUM","LOW"))) -> MEDIUM | W11: 48
A12: TXN00011 | B12: 357.74 | C12: 10 | D12: USA | E12: {=_xlfn.IFS(AND(W12>=18,W12<=25),"18-25",AND(W12>25,W12<=35),"26-35",AND(W12>35,W12<=45),"36-45",AND(W12>45,W12<=55),"46-55",AND(W12>55,W12<=65),"56-65",W12>65,"65+")} -> 26-35 | F12: 6 | G12: 10/22/2025 | H12: =IF(OR(D12="Nigeria",D12="Bangladesh",D12="Pakistan",D12="North Korea",D12="Iran",D12="Syria"),1,0) -> 0 | I12: =IF(AND(C12>=2,C12<=5),1,0) -> 0 | J12: =IF(B12>5000,1,0) -> 0 | K12: =IF(F12>=3,1,0) -> 1 | L12: =IF(AND(B12>5000,C12>=2,C12<=5,H12=1),5,0) + IF(AND(B12>5000,H12=1),3,0) + IF(AND(C12>=2,C12<=5,B12>3000),2,0) + IF(F12>=5,2,0) + IF(AND(W12<25,B12>8000),1,0) + IF(AND(H12=1,B12>3000),2,0) -> 2 | M12: =IF(L12>=10,"CRITICAL",IF(L12>=7,"HIGH",IF(L12>=4,"MEDIUM","LOW"))) -> LOW | W12: 27
A13: TXN00012 | B13: 14550.15 | C13: 23 | D13: Bangladesh | E13: {=_xlfn.IFS(AND(W13>=18,W13<=25),"18-25",AND(W13>25,W13<=35),"26-35",AND(W13>35,W13<=45),"36-45",AND(W13>45,W13<=55),"46-55",AND(W13>55,W13<=65),"56-65",W13>65,"65+")} -> 65+ | F13: 1 | G13: 10/24/2025 | H13: =IF(OR(D13="Nigeria",D13="Bangladesh",D13="Pakistan",D13="North Korea",D13="Iran",D13="Syria"),1,0) -> 1 | I13: =IF(AND(C13>=2,C13<=5),1,0) -> 0 | J13: =IF(B13>5000,1,0) -> 1 | K13: =IF(F13>=3,1,0) -> 0 | L13: =IF(AND(B13>5000,C13>=2,C13<=5,H13=1),5,0) + IF(AND(B13>5000,H13=1),3,0) + IF(AND(C13>=2,C13<=5,B13>3000),2,0) + IF(F13>=5,2,0) + IF(AND(W13<25,B13>8000),1,0) + IF(AND(H13=1,B13>3000),2,0) -> 5 | M13: =IF(L13>=10,"CRITICAL",IF(L13>=7,"HIGH",IF(L13>=4,"MEDIUM","LOW"))) -> MEDIUM | W13: 75
A14: TXN00013 | B14: 12495.02 | C14: 16 | D14: Australia | E14: {=_xlfn.IFS(AND(W14>=18,W14<=25),"18-25",AND(W14>25,W14<=35),"26-35",AND(W14>35,W14<=45),"36-45",AND(W14>45,W14<=55),"46-55",AND(W14>55,W14<=65),"56-65",W14>65,"65+")} -> 36-45 | F14: 8 | G14: 10/18/2025 | H14: =IF(OR(D14="Nigeria",D14="Bangladesh",D14="Pakistan",D14="North Korea",D14="Iran",D14="Syria"),1,0) -> 0 | I14: =IF(AND(C14>=2,C14<=5),1,0) -> 0 | J14: =IF(B14>5000,1,0) -> 1 | K14: =IF(F14>=3,1,0) -> 1 | L14: =IF(AND(B14>5000,C14>=2,C14<=5,H14=1),5,0) + IF(AND(B14>5000,H14=1),3,0) + IF(AND(C14>=2,C14<=5,B14>3000),2,0) + IF(F14>=5,2,0) + IF(AND(W14<25,B14>8000),1,0) + IF(AND(H14=1,B14>3000),2,0) -> 2 | M14: =IF(L14>=10,"CRITICAL",IF(L14>=7,"HIGH",IF(L14>=4,"MEDIUM","LOW"))) -> LOW | W14: 36
A15: TXN00014 | B15: 3224.47 | C15: 5 | D15: Germany | E15: {=_xlfn.IFS(AND(W15>=18,W15<=25),"18-25",AND(W15>25,W15<=35),"26-35",AND(W15>35,W15<=45),"36-45",AND(W15>45,W15<=55),"46-55",AND(W15>55,W15<=65),"56-65",W15>65,"65+")} -> 65+ | F15: 9 | G15: 10/03/2025 | H15: =IF(OR(D15="Nigeria",D15="Bangladesh",D15="Pakistan",D15="North Korea",D15="Iran",D15="Syria"),1,0) -> 0 | I15: =IF(AND(C15>=2,C15<=5),1,0) -> 1 | J15: =IF(B15>5000,1,0) -> 0 | K15: =IF(F15>=3,1,0) -> 1 | L15: =IF(AND(B15>5000,C15>=2,C15<=5,H15=1),5,0) + IF(AND(B15>5000,H15=1),3,0) + IF(AND(C15>=2,C15<=5,B15>3000),2,0) + IF(F15>=5,2,0) + IF(AND(W15<25,B15>8000),1,0) + IF(AND(H15=1,B15>3000),2,0) -> 4 | M15: =IF(L15>=10,"CRITICAL",IF(L15>=7,"HIGH",IF(L15>=4,"MEDIUM","LOW"))) -> MEDIUM | W15: 75
... A127: TXN00126 | B127: 6435.26 | C127: 15 | D127: Japan | E127: {=_xlfn.IFS(AND(W127>=18,W127<=25),"18-25",AND(W127>25,W127<=35),"26-35",AND(W127>35,W127<=45),"36-45",AND(W127>45,W127<=55),"46-55",AND(W127>55,W127<=65),"56-65",W127>65,"65+")} -> 26-35 | F127: 0 | G127: 10/13/2025 | H127: =IF(OR(D127="Nigeria",D127="Bangladesh",D127="Pakistan",D127="North Korea",D127="Iran",D127="Syria"),1,0) -> 0 | I127: =IF(AND(C127>=2,C127<=5),1,0) -> 0 | J127: =IF(B127>5000,1,0) -> 1 | K127: =IF(F127>=3,1,0) -> 0 | L127: =IF(AND(B127>5000,C127>=2,C127<=5,H127=1),5,0) + IF(AND(B127>5000,H127=1),3,0) + IF(AND(C127>=2,C127<=5,B127>3000),2,0) + IF(F127>=5,2,0) + IF(AND(W127<25,B127>8000),1,0) + IF(AND(H127=1,B127>3000),2,0) -> 0 | M127: =IF(L127>=10,"CRITICAL",IF(L127>=7,"HIGH",IF(L127>=4,"MEDIUM","LOW"))) -> LOW | W127: 29
A128: TXN00127 | B128: 12279.32 | C128: 18 | D128: Germany | E128: {=_xlfn.IFS(AND(W128>=18,W128<=25),"18-25",AND(W128>25,W128<=35),"26-35",AND(W128>35,W128<=45),"36-45",AND(W128>45,W128<=55),"46-55",AND(W128>55,W128<=65),"56-65",W128>65,"65+")} -> 65+ | F128: 0 | G128: 10/21/2025 | H128: =IF(OR(D128="Nigeria",D128="Bangladesh",D128="Pakistan",D128="North Korea",D128="Iran",D128="Syria"),1,0) -> 0 | I128: =IF(AND(C128>=2,C128<=5),1,0) -> 0 | J128: =IF(B128>5000,1,0) -> 1 | K128: =IF(F128>=3,1,0) -> 0 | L128: =IF(AND(B128>5000,C128>=2,C128<=5,H128=1),5,0) + IF(AND(B128>5000,H128=1),3,0) + IF(AND(C128>=2,C128<=5,B128>3000),2,0) + IF(F128>=5,2,0) + IF(AND(W128<25,B128>8000),1,0) + IF(AND(H128=1,B128>3000),2,0) -> 0 | M128: =IF(L128>=10,"CRITICAL",IF(L128>=7,"HIGH",IF(L128>=4,"MEDIUM","LOW"))) -> LOW | O128: =COUNTIF(M:M,"Critical") -> 7 | W128: 78
A129: TXN00128 | B129: 12917.92 | C129: 3 | D129: Pakistan | E129: {=_xlfn.IFS(AND(W129>=18,W129<=25),"18-25",AND(W129>25,W129<=35),"26-35",AND(W129>35,W129<=45),"36-45",AND(W129>45,W129<=55),"46-55",AND(W129>55,W129<=65),"56-65",W129>65,"65+")} -> 56-65 | F129: 1 | G129: 10/15/2025 | H129: =IF(OR(D129="Nigeria",D129="Bangladesh",D129="Pakistan",D129="North Korea",D129="Iran",D129="Syria"),1,0) -> 1 | I129: =IF(AND(C129>=2,C129<=5),1,0) -> 1 | J129: =IF(B129>5000,1,0) -> 1 | K129: =IF(F129>=3,1,0) -> 0 | L129: =IF(AND(B129>5000,C129>=2,C129<=5,H129=1),5,0) + IF(AND(B129>5000,H129=1),3,0) + IF(AND(C129>=2,C129<=5,B129>3000),2,0) + IF(F129>=5,2,0) + IF(AND(W129<25,B129>8000),1,0) + IF(AND(H129=1,B129>3000),2,0) -> 12 | M129: =IF(L129>=10,"CRITICAL",IF(L129>=7,"HIGH",IF(L129>=4,"MEDIUM","LOW"))) -> CRITICAL | W129: 58
A130: TXN00129 | B130: 153.93 | C130: 2 | D130: Iran | E130: {=_xlfn.IFS(AND(W130>=18,W130<=25),"18-25",AND(W130>25,W130<=35),"26-35",AND(W130>35,W130<=45),"36-45",AND(W130>45,W130<=55),"46-55",AND(W130>55,W130<=65),"56-65",W130>65,"65+")} -> 36-45 | F130: 8 | G130: 10/05/2025 | H130: =IF(OR(D130="Nigeria",D130="Bangladesh",D130="Pakistan",D130="North Korea",D130="Iran",D130="Syria"),1,0) -> 1 | I130: =IF(AND(C130>=2,C130<=5),1,0) -> 1 | J130: =IF(B130>5000,1,0) -> 0 | K130: =IF(F130>=3,1,0) -> 1 | L130: =IF(AND(B130>5000,C130>=2,C130<=5,H130=1),5,0) + IF(AND(B130>5000,H130=1),3,0) + IF(AND(C130>=2,C130<=5,B130>3000),2,0) + IF(F130>=5,2,0) + IF(AND(W130<25,B130>8000),1,0) + IF(AND(H130=1,B130>3000),2,0) -> 2 | M130: =IF(L130>=10,"CRITICAL",IF(L130>=7,"HIGH",IF(L130>=4,"MEDIUM","LOW"))) -> LOW | W130: 36
A131: TXN00130 | B131: 7685.67 | C131: 16 | D131: Syria | E131: {=_xlfn.IFS(AND(W131>=18,W131<=25),"18-25",AND(W131>25,W131<=35),"26-35",AND(W131>35,W131<=45),"36-45",AND(W131>45,W131<=55),"46-55",AND(W131>55,W131<=65),"56-65",W131>65,"65+")} -> 26-35 | F131: 2 | G131: 10/09/2025 | H131: =IF(OR(D131="Nigeria",D131="Bangladesh",D131="Pakistan",D131="North Korea",D131="Iran",D131="Syria"),1,0) -> 1 | I131: =IF(AND(C131>=2,C131<=5),1,0) -> 0 | J131: =IF(B131>5000,1,0) -> 1 | K131: =IF(F131>=3,1,0) -> 0 | L131: =IF(AND(B131>5000,C131>=2,C131<=5,H131=1),5,0) + IF(AND(B131>5000,H131=1),3,0) + IF(AND(C131>=2,C131<=5,B131>3000),2,0) + IF(F131>=5,2,0) + IF(AND(W131<25,B131>8000),1,0) + IF(AND(H131=1,B131>3000),2,0) -> 5 | M131: =IF(L131>=10,"CRITICAL",IF(L131>=7,"HIGH",IF(L131>=4,"MEDIUM","LOW"))) -> MEDIUM | W131: 29
A132: TXN00131 | B132: 6290.29 | C132: 16 | D132: UK | E132: {=_xlfn.IFS(AND(W132>=18,W132<=25),"18-25",AND(W132>25,W132<=35),"26-35",AND(W132>35,W132<=45),"36-45",AND(W132>45,W132<=55),"46-55",AND(W132>55,W132<=65),"56-65",W132>65,"65+")} -> 26-35 | F132: 0 | G132: 10/05/2025 | H132: =IF(OR(D132="Nigeria",D132="Bangladesh",D132="Pakistan",D132="North Korea",D132="Iran",D132="Syria"),1,0) -> 0 | I132: =IF(AND(C132>=2,C132<=5),1,0) -> 0 | J132: =IF(B132>5000,1,0) -> 1 | K132: =IF(F132>=3,1,0) -> 0 | L132: =IF(AND(B132>5000,C132>=2,C132<=5,H132=1),5,0) + IF(AND(B132>5000,H132=1),3,0) + IF(AND(C132>=2,C132<=5,B132>3000),2,0) + IF(F132>=5,2,0) + IF(AND(W132<25,B132>8000),1,0) + IF(AND(H132=1,B132>3000),2,0) -> 0 | M132: =IF(L132>=10,"CRITICAL",IF(L132>=7,"HIGH",IF(L132>=4,"MEDIUM","LOW"))) -> LOW | W132: 26
A133: TXN00132 | B133: 3370.51 | C133: 11 | D133: Singapore | E133: {=_xlfn.IFS(AND(W133>=18,W133<=25),"18-25",AND(W133>25,W133<=35),"26-35",AND(W133>35,W133<=45),"36-45",AND(W133>45,W133<=55),"46-55",AND(W133>55,W133<=65),"56-65",W133>65,"65+")} -> 18-25 | F133: 4 | G133: 10/08/2025 | H133: =IF(OR(D133="Nigeria",D133="Bangladesh",D133="Pakistan",D133="North Korea",D133="Iran",D133="Syria"),1,0) -> 0 | I133: =IF(AND(C133>=2,C133<=5),1,0) -> 0 | J133: =IF(B133>5000,1,0) -> 0 | K133: =IF(F133>=3,1,0) -> 1 | L133: =IF(AND(B133>5000,C133>=2,C133<=5,H133=1),5,0) + IF(AND(B133>5000,H133=1),3,0) + IF(AND(C133>=2,C133<=5,B133>3000),2,0) + IF(F133>=5,2,0) + IF(AND(W133<25,B133>8000),1,0) + IF(AND(H133=1,B133>3000),2,0) -> 0 | M133: =IF(L133>=10,"CRITICAL",IF(L133>=7,"HIGH",IF(L133>=4,"MEDIUM","LOW"))) -> LOW | W133: 24
A134: TXN00133 | B134: 1841.99 | C134: 13 | D134: Netherlands | E134: {=_xlfn.IFS(AND(W134>=18,W134<=25),"18-25",AND(W134>25,W134<=35),"26-35",AND(W134>35,W134<=45),"36-45",AND(W134>45,W134<=55),"46-55",AND(W134>55,W134<=65),"56-65",W134>65,"65+")} -> 36-45 | F134: 6 | G134: 10/24/2025 | H134: =IF(OR(D134="Nigeria",D134="Bangladesh",D134="Pakistan",D134="North Korea",D134="Iran",D134="Syria"),1,0) -> 0 | I134: =IF(AND(C134>=2,C134<=5),1,0) -> 0 | J134: =IF(B134>5000,1,0) -> 0 | K134: =IF(F134>=3,1,0) -> 1 | L134: =IF(AND(B134>5000,C134>=2,C134<=5,H134=1),5,0) + IF(AND(B134>5000,H134=1),3,0) + IF(AND(C134>=2,C134<=5,B134>3000),2,0) + IF(F134>=5,2,0) + IF(AND(W134<25,B134>8000),1,0) + IF(AND(H134=1,B134>3000),2,0) -> 2 | M134: =IF(L134>=10,"CRITICAL",IF(L134>=7,"HIGH",IF(L134>=4,"MEDIUM","LOW"))) -> LOW | W134: 45
A135: TXN00134 | B135: 5097.35 | C135: 20 | D135: Japan | E135: {=_xlfn.IFS(AND(W135>=18,W135<=25),"18-25",AND(W135>25,W135<=35),"26-35",AND(W135>35,W135<=45),"36-45",AND(W135>45,W135<=55),"46-55",AND(W135>55,W135<=65),"56-65",W135>65,"65+")} -> 26-35 | F135: 5 | G135: 10/18/2025 | H135: =IF(OR(D135="Nigeria",D135="Bangladesh",D135="Pakistan",D135="North Korea",D135="Iran",D135="Syria"),1,0) -> 0 | I135: =IF(AND(C135>=2,C135<=5),1,0) -> 0 | J135: =IF(B135>5000,1,0) -> 1 | K135: =IF(F135>=3,1,0) -> 1 | L135: =IF(AND(B135>5000,C135>=2,C135<=5,H135=1),5,0) + IF(AND(B135>5000,H135=1),3,0) + IF(AND(C135>=2,C135<=5,B135>3000),2,0) + IF(F135>=5,2,0) + IF(AND(W135<25,B135>8000),1,0) + IF(AND(H135=1,B135>3000),2,0) -> 2 | M135: =IF(L135>=10,"CRITICAL",IF(L135>=7,"HIGH",IF(L135>=4,"MEDIUM","LOW"))) -> LOW | W135: 31
A136: TXN00135 | B136: 14146.5 | C136: 5 | D136: Iran | E136: {=_xlfn.IFS(AND(W136>=18,W136<=25),"18-25",AND(W136>25,W136<=35),"26-35",AND(W136>35,W136<=45),"36-45",AND(W136>45,W136<=55),"46-55",AND(W136>55,W136<=65),"56-65",W136>65,"65+")} -> 46-55 | F136: 0 | G136: 10/18/2025 | H136: =IF(OR(D136="Nigeria",D136="Bangladesh",D136="Pakistan",D136="North Korea",D136="Iran",D136="Syria"),1,0) -> 1 | I136: =IF(AND(C136>=2,C136<=5),1,0) -> 1 | J136: =IF(B136>5000,1,0) -> 1 | K136: =IF(F136>=3,1,0) -> 0 | L136: =IF(AND(B136>5000,C136>=2,C136<=5,H136=1),5,0) + IF(AND(B136>5000,H136=1),3,0) + IF(AND(C136>=2,C136<=5,B136>3000),2,0) + IF(F136>=5,2,0) + IF(AND(W136<25,B136>8000),1,0) + IF(AND(H136=1,B136>3000),2,0) -> 12 | M136: =IF(L136>=10,"CRITICAL",IF(L136>=7,"HIGH",IF(L136>=4,"MEDIUM","LOW"))) -> CRITICAL | W136: 48
A137: TXN00136 | B137: 4881.88 | C137: 2 | D137: Nigeria | E137: {=_xlfn.IFS(AND(W137>=18,W137<=25),"18-25",AND(W137>25,W137<=35),"26-35",AND(W137>35,W137<=45),"36-45",AND(W137>45,W137<=55),"46-55",AND(W137>55,W137<=65),"56-65",W137>65,"65+")} -> 65+ | F137: 4 | G137: 10/09/2025 | H137: =IF(OR(D137="Nigeria",D137="Bangladesh",D137="Pakistan",D137="North Korea",D137="Iran",D137="Syria"),1,0) -> 1 | I137: =IF(AND(C137>=2,C137<=5),1,0) -> 1 | J137: =IF(B137>5000,1,0) -> 0 | K137: =IF(F137>=3,1,0) -> 1 | L137: =IF(AND(B137>5000,C137>=2,C137<=5,H137=1),5,0) + IF(AND(B137>5000,H137=1),3,0) + IF(AND(C137>=2,C137<=5,B137>3000),2,0) + IF(F137>=5,2,0) + IF(AND(W137<25,B137>8000),1,0) + IF(AND(H137=1,B137>3000),2,0) -> 4 | M137: =IF(L137>=10,"CRITICAL",IF(L137>=7,"HIGH",IF(L137>=4,"MEDIUM","LOW"))) -> MEDIUM | W137: 69
A138: TXN00137 | B138: 7805.92 | C138: 8 | D138: Netherlands | E138: {=_xlfn.IFS(AND(W138>=18,W138<=25),"18-25",AND(W138>25,W138<=35),"26-35",AND(W138>35,W138<=45),"36-45",AND(W138>45,W138<=55),"46-55",AND(W138>55,W138<=65),"56-65",W138>65,"65+")} -> 36-45 | F138: 4 | G138: 10/24/2025 | H138: =IF(OR(D138="Nigeria",D138="Bangladesh",D138="Pakistan",D138="North Korea",D138="Iran",D138="Syria"),1,0) -> 0 | I138: =IF(AND(C138>=2,C138<=5),1,0) -> 0 | J138: =IF(B138>5000,1,0) -> 1 | K138: =IF(F138>=3,1,0) -> 1 | L138: =IF(AND(B138>5000,C138>=2,C138<=5,H138=1),5,0) + IF(AND(B138>5000,H138=1),3,0) + IF(AND(C138>=2,C138<=5,B138>3000),2,0) + IF(F138>=5,2,0) + IF(AND(W138<25,B138>8000),1,0) + IF(AND(H138=1,B138>3000),2,0) -> 0 | M138: =IF(L138>=10,"CRITICAL",IF(L138>=7,"HIGH",IF(L138>=4,"MEDIUM","LOW"))) -> LOW | W138: 36
A139: TXN00138 | B139: 10560.13 | C139: 4 | D139: Netherlands | E139: {=_xlfn.IFS(AND(W139>=18,W139<=25),"18-25",AND(W139>25,W139<=35),"26-35",AND(W139>35,W139<=45),"36-45",AND(W139>45,W139<=55),"46-55",AND(W139>55,W139<=65),"56-65",W139>65,"65+")} -> 65+ | F139: 5 | G139: 10/19/2025 | H139: =IF(OR(D139="Nigeria",D139="Bangladesh",D139="Pakistan",D139="North Korea",D139="Iran",D139="Syria"),1,0) -> 0 | I139: =IF(AND(C139>=2,C139<=5),1,0) -> 1 | J139: =IF(B139>5000,1,0) -> 1 | K139: =IF(F139>=3,1,0) -> 1 | L139: =IF(AND(B139>5000,C139>=2,C139<=5,H139=1),5,0) + IF(AND(B139>5000,H139=1),3,0) + IF(AND(C139>=2,C139<=5,B139>3000),2,0) + IF(F139>=5,2,0) + IF(AND(W139<25,B139>8000),1,0) + IF(AND(H139=1,B139>3000),2,0) -> 4 | M139: =IF(L139>=10,"CRITICAL",IF(L139>=7,"HIGH",IF(L139>=4,"MEDIUM","LOW"))) -> MEDIUM | W139: 75
A140: TXN00139 | B140: 5486.26 | C140: 23 | D140: Netherlands | E140: {=_xlfn.IFS(AND(W140>=18,W140<=25),"18-25",AND(W140>25,W140<=35),"26-35",AND(W140>35,W140<=45),"36-45",AND(W140>45,W140<=55),"46-55",AND(W140>55,W140<=65),"56-65",W140>65,"65+")} -> 56-65 | F140: 2 | G140: 10/14/2025 | H140: =IF(OR(D140="Nigeria",D140="Bangladesh",D140="Pakistan",D140="North Korea",D140="Iran",D140="Syria"),1,0) -> 0 | I140: =IF(AND(C140>=2,C140<=5),1,0) -> 0 | J140: =IF(B140>5000,1,0) -> 1 | K140: =IF(F140>=3,1,0) -> 0 | L140: =IF(AND(B140>5000,C140>=2,C140<=5,H140=1),5,0) + IF(AND(B140>5000,H140=1),3,0) + IF(AND(C140>=2,C140<=5,B140>3000),2,0) + IF(F140>=5,2,0) + IF(AND(W140<25,B140>8000),1,0) + IF(AND(H140=1,B140>3000),2,0) -> 0 | M140: =IF(L140>=10,"CRITICAL",IF(L140>=7,"HIGH",IF(L140>=4,"MEDIUM","LOW"))) -> LOW | W140: 64
... A151: TXN00150 | B151: 4215.76 | C151: 17 | D151: Netherlands | E151: {=_xlfn.IFS(AND(W151>=18,W151<=25),"18-25",AND(W151>25,W151<=35),"26-35",AND(W151>35,W151<=45),"36-45",AND(W151>45,W151<=55),"46-55",AND(W151>55,W151<=65),"56-65",W151>65,"65+")} -> 65+ | F151: 8 | G151: 10/04/2025 | H151: =IF(OR(D151="Nigeria",D151="Bangladesh",D151="Pakistan",D151="North Korea",D151="Iran",D151="Syria"),1,0) -> 0 | I151: =IF(AND(C151>=2,C151<=5),1,0) -> 0 | J151: =IF(B151>5000,1,0) -> 0 | K151: =IF(F151>=3,1,0) -> 1 | L151: =IF(AND(B151>5000,C151>=2,C151<=5,H151=1),5,0) + IF(AND(B151>5000,H151=1),3,0) + IF(AND(C151>=2,C151<=5,B151>3000),2,0) + IF(F151>=5,2,0) + IF(AND(W151<25,B151>8000),1,0) + IF(AND(H151=1,B151>3000),2,0) -> 2 | M151: =IF(L151>=10,"CRITICAL",IF(L151>=7,"HIGH",IF(L151>=4,"MEDIUM","LOW"))) -> LOW | W151: 70

Sheet Analysis - Location & Time
A1: RISK ANALYSIS BY LOCATION
A2: Country | B2: Count | C2: Avg Risk Score | D2: Max Risk Score | E2: High Risk % | F2: Total Amount
A3: Australia | B3: =COUNTIF(Transactions!$D$2:$D$151,A3) -> 3 | C3: =AVERAGEIF(Transactions!$D$2:$D$151,A3,Transactions!$L$2:$L$151) -> 1.3333333 | D3: =_xlfn.MAXIFS(Transactions!$L$2:$L$151,Transactions!$D$2:$D$151,A3) -> 2 | E3: =COUNTIFS(Transactions!$D$2:$D$151,A3,Transactions!$M$2:$M$151,"CRITICAL")/B3 -> 0 | F3: =SUMIF(Transactions!$D$2:$D$151,A3,Transactions!$B$2:$B$151) -> 29855.53
A4: Bangladesh | B4: =COUNTIF(Transactions!$D$2:$D$151,A4) -> 8 | C4: =AVERAGEIF(Transactions!$D$2:$D$151,A4,Transactions!$L$2:$L$151) -> 6.75 | D4: =_xlfn.MAXIFS(Transactions!$L$2:$L$151,Transactions!$D$2:$D$151,A4) -> 14 | E4: =COUNTIFS(Transactions!$D$2:$D$151,A4,Transactions!$M$2:$M$151,"CRITICAL")/B4 -> 0.25 | F4: =SUMIF(Transactions!$D$2:$D$151,A4,Transactions!$B$2:$B$151) -> 66649.43
A5: Canada | B5: =COUNTIF(Transactions!$D$2:$D$151,A5) -> 9 | C5: =AVERAGEIF(Transactions!$D$2:$D$151,A5,Transactions!$L$2:$L$151) -> 2.2222222 | D5: =_xlfn.MAXIFS(Transactions!$L$2:$L$151,Transactions!$D$2:$D$151,A5) -> 4 | E5: =COUNTIFS(Transactions!$D$2:$D$151,A5,Transactions!$M$2:$M$151,"CRITICAL")/B5 -> 0 | F5: =SUMIF(Transactions!$D$2:$D$151,A5,Transactions!$B$2:$B$151) -> 71031.12
A6: Germany | B6: =COUNTIF(Transactions!$D$2:$D$151,A6) -> 20 | C6: =AVERAGEIF(Transactions!$D$2:$D$151,A6,Transactions!$L$2:$L$151) -> 1.4 | D6: =_xlfn.MAXIFS(Transactions!$L$2:$L$151,Transactions!$D$2:$D$151,A6) -> 4 | E6: =COUNTIFS(Transactions!$D$2:$D$151,A6,Transactions!$M$2:$M$151,"CRITICAL")/B6 -> 0 | F6: =SUMIF(Transactions!$D$2:$D$151,A6,Transactions!$B$2:$B$151) -> 150970.22
A7: Iran | B7: =COUNTIF(Transactions!$D$2:$D$151,A7) -> 12 | C7: =AVERAGEIF(Transactions!$D$2:$D$151,A7,Transactions!$L$2:$L$151) -> 4.3333333 | D7: =_xlfn.MAXIFS(Transactions!$L$2:$L$151,Transactions!$D$2:$D$151,A7) -> 12 | E7: =COUNTIFS(Transactions!$D$2:$D$151,A7,Transactions!$M$2:$M$151,"CRITICAL")/B7 -> 0.083333333 | F7: =SUMIF(Transactions!$D$2:$D$151,A7,Transactions!$B$2:$B$151) -> 96215.75
A8: Japan | B8: =COUNTIF(Transactions!$D$2:$D$151,A8) -> 13 | C8: =AVERAGEIF(Transactions!$D$2:$D$151,A8,Transactions!$L$2:$L$151) -> 1 | D8: =_xlfn.MAXIFS(Transactions!$L$2:$L$151,Transactions!$D$2:$D$151,A8) -> 2 | E8: =COUNTIFS(Transactions!$D$2:$D$151,A8,Transactions!$M$2:$M$151,"CRITICAL")/B8 -> 0 | F8: =SUMIF(Transactions!$D$2:$D$151,A8,Transactions!$B$2:$B$151) -> 87050.59
A9: Netherlands | B9: =COUNTIF(Transactions!$D$2:$D$151,A9) -> 14 | C9: =AVERAGEIF(Transactions!$D$2:$D$151,A9,Transactions!$L$2:$L$151) -> 1.6428571 | D9: =_xlfn.MAXIFS(Transactions!$L$2:$L$151,Transactions!$D$2:$D$151,A9) -> 4 | E9: =COUNTIFS(Transactions!$D$2:$D$151,A9,Transactions!$M$2:$M$151,"CRITICAL")/B9 -> 0 | F9: =SUMIF(Transactions!$D$2:$D$151,A9,Transactions!$B$2:$B$151) -> 80741.23
A10: Nigeria | B10: =COUNTIF(Transactions!$D$2:$D$151,A10) -> 11 | C10: =AVERAGEIF(Transactions!$D$2:$D$151,A10,Transactions!$L$2:$L$151) -> 4.8181818 | D10: =_xlfn.MAXIFS(Transactions!$L$2:$L$151,Transactions!$D$2:$D$151,A10) -> 14 | E10: =COUNTIFS(Transactions!$D$2:$D$151,A10,Transactions!$M$2:$M$151,"CRITICAL")/B10 -> 0.090909091 | F10: =SUMIF(Transactions!$D$2:$D$151,A10,Transactions!$B$2:$B$151) -> 58146.77
A11: North Korea | B11: =COUNTIF(Transactions!$D$2:$D$151,A11) -> 8 | C11: =AVERAGEIF(Transactions!$D$2:$D$151,A11,Transactions!$L$2:$L$151) -> 3.75 | D11: =_xlfn.MAXIFS(Transactions!$L$2:$L$151,Transactions!$D$2:$D$151,A11) -> 5 | E11: =COUNTIFS(Transactions!$D$2:$D$151,A11,Transactions!$M$2:$M$151,"CRITICAL")/B11 -> 0 | F11: =SUMIF(Transactions!$D$2:$D$151,A11,Transactions!$B$2:$B$151) -> 60792.98
A12: Pakistan | B12: =COUNTIF(Transactions!$D$2:$D$151,A12) -> 9 | C12: =AVERAGEIF(Transactions!$D$2:$D$151,A12,Transactions!$L$2:$L$151) -> 7.1111111 | D12: =_xlfn.MAXIFS(Transactions!$L$2:$L$151,Transactions!$D$2:$D$151,A12) -> 14 | E12: =COUNTIFS(Transactions!$D$2:$D$151,A12,Transactions!$M$2:$M$151,"CRITICAL")/B12 -> 0.33333333 | F12: =SUMIF(Transactions!$D$2:$D$151,A12,Transactions!$B$2:$B$151) -> 61700.16
A13: Singapore | B13: =COUNTIF(Transactions!$D$2:$D$151,A13) -> 10 | C13: =AVERAGEIF(Transactions!$D$2:$D$151,A13,Transactions!$L$2:$L$151) -> 1.2 | D13: =_xlfn.MAXIFS(Transactions!$L$2:$L$151,Transactions!$D$2:$D$151,A13) -> 4 | E13: =COUNTIFS(Transactions!$D$2:$D$151,A13,Transactions!$M$2:$M$151,"CRITICAL")/B13 -> 0 | F13: =SUMIF(Transactions!$D$2:$D$151,A13,Transactions!$B$2:$B$151) -> 68435.98
A14: Syria | B14: =COUNTIF(Transactions!$D$2:$D$151,A14) -> 12 | C14: =AVERAGEIF(Transactions!$D$2:$D$151,A14,Transactions!$L$2:$L$151) -> 4.25 | D14: =_xlfn.MAXIFS(Transactions!$L$2:$L$151,Transactions!$D$2:$D$151,A14) -> 7 | E14: =COUNTIFS(Transactions!$D$2:$D$151,A14,Transactions!$M$2:$M$151,"CRITICAL")/B14 -> 0 | F14: =SUMIF(Transactions!$D$2:$D$151,A14,Transactions!$B$2:$B$151) -> 90467.98
... A16: USA | B16: =COUNTIF(Transactions!$D$2:$D$151,A16) -> 13 | C16: =AVERAGEIF(Transactions!$D$2:$D$151,A16,Transactions!$L$2:$L$151) -> 1.2307692 | D16: =_xlfn.MAXIFS(Transactions!$L$2:$L$151,Transactions!$D$2:$D$151,A16) -> 2 | E16: =COUNTIFS(Transactions!$D$2:$D$151,A16,Transactions!$M$2:$M$151,"CRITICAL")/B16 -> 0 | F16: =SUMIF(Transactions!$D$2:$D$151,A16,Transactions!$B$2:$B$151) -> 82788.14
A18: RISK ANALYSIS BY TIME OF DAY
A20: Hour | B20: Count | C20: Avg Risk Score | D20: High Risk Count
A21: 0 | B21: =COUNTIF(Transactions!$C$2:$C$151,0) -> 14 | C21: =AVERAGEIF(Transactions!$C$2:$C$151,0,Transactions!$L$2:$L$151) -> 2.4285714 | D21: =COUNTIFS(Transactions!$C$2:$C$151,0,Transactions!$M$2:$M$151,"CRITICAL") -> 0
A22: 1 | B22: =COUNTIF(Transactions!$C$2:$C$151,1) -> 5 | C22: =AVERAGEIF(Transactions!$C$2:$C$151,1,Transactions!$L$2:$L$151) -> 0.8 | D22: =COUNTIFS(Transactions!$C$2:$C$151,1,Transactions!$M$2:$M$151,"CRITICAL") -> 0
A23: 2 | B23: =COUNTIF(Transactions!$C$2:$C$151,2) -> 13 | C23: =AVERAGEIF(Transactions!$C$2:$C$151,2,Transactions!$L$2:$L$151) -> 4.4615385 | D23: =COUNTIFS(Transactions!$C$2:$C$151,2,Transactions!$M$2:$M$151,"CRITICAL") -> 3
A24: 3 | B24: =COUNTIF(Transactions!$C$2:$C$151,3) -> 6 | C24: =AVERAGEIF(Transactions!$C$2:$C$151,3,Transactions!$L$2:$L$151) -> 5.3333333 | D24: =COUNTIFS(Transactions!$C$2:$C$151,3,Transactions!$M$2:$M$151,"CRITICAL") -> 2
A25: 4 | B25: =COUNTIF(Transactions!$C$2:$C$151,4) -> 5 | C25: =AVERAGEIF(Transactions!$C$2:$C$151,4,Transactions!$L$2:$L$151) -> 2.4 | D25: =COUNTIFS(Transactions!$C$2:$C$151,4,Transactions!$M$2:$M$151,"CRITICAL") -> 0
A26: 5 | B26: =COUNTIF(Transactions!$C$2:$C$151,5) -> 8 | C26: =AVERAGEIF(Transactions!$C$2:$C$151,5,Transactions!$L$2:$L$151) -> 5.5 | D26: =COUNTIFS(Transactions!$C$2:$C$151,5,Transactions!$M$2:$M$151,"CRITICAL") -> 2
A27: 6 | B27: =COUNTIF(Transactions!$C$2:$C$151,6) -> 4 | C27: =AVERAGEIF(Transactions!$C$2:$C$151,6,Transactions!$L$2:$L$151) -> 3.5 | D27: =COUNTIFS(Transactions!$C$2:$C$151,6,Transactions!$M$2:$M$151,"CRITICAL") -> 0
A28: 7 | B28: =COUNTIF(Transactions!$C$2:$C$151,7) -> 6 | C28: =AVERAGEIF(Transactions!$C$2:$C$151,7,Transactions!$L$2:$L$151) -> 2 | D28: =COUNTIFS(Transactions!$C$2:$C$151,7,Transactions!$M$2:$M$151,"CRITICAL") -> 0
A29: 8 | B29: =COUNTIF(Transactions!$C$2:$C$151,8) -> 6 | C29: =AVERAGEIF(Transactions!$C$2:$C$151,8,Transactions!$L$2:$L$151) -> 3 | D29: =COUNTIFS(Transactions!$C$2:$C$151,8,Transactions!$M$2:$M$151,"CRITICAL") -> 0
A30: 9 | B30: =COUNTIF(Transactions!$C$2:$C$151,9) -> 1 | C30: =AVERAGEIF(Transactions!$C$2:$C$151,9,Transactions!$L$2:$L$151) -> 0 | D30: =COUNTIFS(Transactions!$C$2:$C$151,9,Transactions!$M$2:$M$151,"CRITICAL") -> 0
A31: 10 | B31: =COUNTIF(Transactions!$C$2:$C$151,10) -> 4 | C31: =AVERAGEIF(Transactions!$C$2:$C$151,10,Transactions!$L$2:$L$151) -> 2.5 | D31: =COUNTIFS(Transactions!$C$2:$C$151,10,Transactions!$M$2:$M$151,"CRITICAL") -> 0
A32: 11 | B32: =COUNTIF(Transactions!$C$2:$C$151,11) -> 4 | C32: =AVERAGEIF(Transactions!$C$2:$C$151,11,Transactions!$L$2:$L$151) -> 1 | D32: =COUNTIFS(Transactions!$C$2:$C$151,11,Transactions!$M$2:$M$151,"CRITICAL") -> 0
A33: 12 | B33: =COUNTIF(Transactions!$C$2:$C$151,12) -> 1 | C33: =AVERAGEIF(Transactions!$C$2:$C$151,12,Transactions!$L$2:$L$151) -> 2 | D33: =COUNTIFS(Transactions!$C$2:$C$151,12,Transactions!$M$2:$M$151,"CRITICAL") -> 0
A34: 13 | B34: =COUNTIF(Transactions!$C$2:$C$151,13) -> 5 | C34: =AVERAGEIF(Transactions!$C$2:$C$151,13,Transactions!$L$2:$L$151) -> 3.2 | D34: =COUNTIFS(Transactions!$C$2:$C$151,13,Transactions!$M$2:$M$151,"CRITICAL") -> 0
A35: 14 | B35: =COUNTIF(Transactions!$C$2:$C$151,14) -> 1 | C35: =AVERAGEIF(Transactions!$C$2:$C$151,14,Transactions!$L$2:$L$151) -> 2 | D35: =COUNTIFS(Transactions!$C$2:$C$151,14,Transactions!$M$2:$M$151,"CRITICAL") -> 0
A36: 15 | B36: =COUNTIF(Transactions!$C$2:$C$151,15) -> 13 | C36: =AVERAGEIF(Transactions!$C$2:$C$151,15,Transactions!$L$2:$L$151) -> 2 | D36: =COUNTIFS(Transactions!$C$2:$C$151,15,Transactions!$M$2:$M$151,"CRITICAL") -> 0
A37: 16 | B37: =COUNTIF(Transactions!$C$2:$C$151,16) -> 7 | C37: =AVERAGEIF(Transactions!$C$2:$C$151,16,Transactions!$L$2:$L$151) -> 2 | D37: =COUNTIFS(Transactions!$C$2:$C$151,16,Transactions!$M$2:$M$151,"CRITICAL") -> 0
A38: 17 | B38: =COUNTIF(Transactions!$C$2:$C$151,17) -> 5 | C38: =AVERAGEIF(Transactions!$C$2:$C$151,17,Transactions!$L$2:$L$151) -> 3.4 | D38: =COUNTIFS(Transactions!$C$2:$C$151,17,Transactions!$M$2:$M$151,"CRITICAL") -> 0
A39: 18 | B39: =COUNTIF(Transactions!$C$2:$C$151,18) -> 7 | C39: =AVERAGEIF(Transactions!$C$2:$C$151,18,Transactions!$L$2:$L$151) -> 3 | D39: =COUNTIFS(Transactions!$C$2:$C$151,18,Transactions!$M$2:$M$151,"CRITICAL") -> 0
A40: 19 | B40: =COUNTIF(Transactions!$C$2:$C$151,19) -> 10 | C40: =AVERAGEIF(Transactions!$C$2:$C$151,19,Transactions!$L$2:$L$151) -> 3.5 | D40: =COUNTIFS(Transactions!$C$2:$C$151,19,Transactions!$M$2:$M$151,"CRITICAL") -> 0
A41: 20 | B41: =COUNTIF(Transactions!$C$2:$C$151,20) -> 6 | C41: =AVERAGEIF(Transactions!$C$2:$C$151,20,Transactions!$L$2:$L$151) -> 2.1666667 | D41: =COUNTIFS(Transactions!$C$2:$C$151,20,Transactions!$M$2:$M$151,"CRITICAL") -> 0
A42: 21 | B42: =COUNTIF(Transactions!$C$2:$C$151,21) -> 6 | C42: =AVERAGEIF(Transactions!$C$2:$C$151,21,Transactions!$L$2:$L$151) -> 1.3333333 | D42: =COUNTIFS(Transactions!$C$2:$C$151,21,Transactions!$M$2:$M$151,"CRITICAL") -> 0
A43: 22 | B43: =COUNTIF(Transactions!$C$2:$C$151,22) -> 6 | C43: =AVERAGEIF(Transactions!$C$2:$C$151,22,Transactions!$L$2:$L$151) -> 3.3333333 | D43: =COUNTIFS(Transactions!$C$2:$C$151,22,Transactions!$M$2:$M$151,"CRITICAL") -> 0
...

Sheet Monthly Summary
A1: MONTHLY HIGH-RISK TRANSACTION SUMMARY
A3: Month | B3: Transaction Count | C3: Total Amount | D3: Critical Risk Count | E3: High Risk Amount | F3: Average Risk Score
A4: 10/2025 | B4: =COUNTIF(Transactions!$G$2:$G$151,"10/*") -> 150 | C4: =SUMIF(Transactions!$B$2:$B$151,">0") -> 1067949.4 | D4: =COUNTIF(Transactions!$M$2:$M$151,"CRITICAL") -> 7 | E4: =SUMIFS(Transactions!$B$2:$B$151,Transactions!$M$2:$M$151,"CRITICAL")+SUMIFS(Transactions!$B$2:$B$151,Transactions!$M$2:$M$151,"HIGH") -> 145405.12 | F4: =AVERAGE(Transactions!$L$2:$L$151) -> 2.8533333

Sheet Chartdata
A1: FRAUD DETECTION RISK SCORER - EXECUTIVE DASHBOARD
A2: Analysis Date: | B2: =TODAY() -> 46009 | C2: KEY PERFORMANCE INDICATORS
A4: Total Transactions | C4: Row Labels | D4: Sum of Risk Score | E4: Count of Transaction ID | F4: Sum of Amount
A5: 150 | C5: Australia | D5: 4 | E5: 3 | F5: 29855.53
A6: Average of Risk Score | C6: Bangladesh | D6: 54 | E6: 8 | F6: 66649.43
A7: 2.8533333 | C7: Canada | D7: 20 | E7: 9 | F7: 71031.12
A8: Total Amount | C8: Germany | D8: 28 | E8: 20 | F8: 150970.22
A9: 1067949.4 | C9: Iran | D9: 52 | E9: 12 | F9: 96215.75
A10: High Risk Country | C10: Japan | D10: 13 | E10: 13 | F10: 87050.59
A11: 60 | C11: Netherlands | D11: 23 | E11: 14 | F11: 80741.23
C12: Nigeria | D12: 53 | E12: 11 | F12: 58146.77
A13: Total Transactions | B13: =COUNTA(Transactions!$A$2:$A$151) -> 150 | C13: North Korea | D13: 30 | E13: 8 | F13: 60792.98
A14: CRITICAL Risk Transactions | B14: =COUNTIF(Transactions!$M$2:$M$151,"CRITICAL") -> 7 | C14: Pakistan | D14: 64 | E14: 9 | F14: 61700.16
A15: HIGH Risk Transactions | B15: =COUNTIF(Transactions!$M$2:$M$151,"HIGH") -> 7 | C15: Singapore | D15: 12 | E15: 10 | F15: 68435.98
A16: Average Risk Score | B16: =AVERAGE(Transactions!$L$2:$L$151) -> 2.8533333 | C16: Syria | D16: 51 | E16: 12 | F16: 90467.98
A17: High-Risk Transaction Value | B17: =SUMIF(Transactions!$M$2:$M$151,"CRITICAL",Transactions!$B$2:$B$151)+SUMIF(Transactions!$M$2:$M$151,"HIGH",Transactions!$B$2:$B$151) -> 145405.12 | C17: UK | D17: 8 | E17: 8 | F17: 63103.55
C18: USA | D18: 16 | E18: 13 | F18: 82788.14
C19: Grand Total | D19: 428 | E19: 150 | F19: 1067949.4
A20: Row Labels | B20: Sum of Amount
A21: 0 | B21: 246754.11
A22: 1 | B22: 13644.34 | D22: Row Labels | E22: Count of Risk Level
A23: 2 | B23: 340138.5 | D23: CRITICAL | E23: 7
A24: 3 | B24: 8988.6 | D24: HIGH | E24: 7
A25: 4 | B25: 92635.15 | D25: LOW | E25: 99
A26: 5 | B26: 216925.98 | D26: MEDIUM | E26: 37
A27: 6 | B27: 3457.63 | D27: Grand Total | E27: 150
A28: 7 | B28: 77865.32
A29: 12 | B29: 43838.89
A30: 14 | B30: 23700.91
A31: Grand Total | B31: 1067949.4

Sheet Instructions
A1: FRAUD DETECTION RISK SCORER - USER GUIDE
A3: PROJECT OVERVIEW
A4: This workbook provides an automated fraud detection system that assigns risk scores to transactions
A5: based on multiple risk factors. The scoring algorithm evaluates transaction characteristics and flags
A6: potentially fraudulent activities for analyst review.
A8: RISK SCORING FORMULA
A9: The Risk Score (Column L) is calculated using nested IF/AND/OR logic:
A10: • 5 points: Amount > $5000 AND Late Night (2-5 AM) AND High-Risk Country
A11: • 3 points: Amount > $5000 AND High-Risk Country
A12: • 2 points: Late Night (2-5 AM) AND Amount > $3000
A13: • 2 points: Prior High-Risk Transactions >= 5
A14: • 1 point: Young Customer (Age < 25) AND Amount > $8000
... A31: In my Fraud Detection Risk Scorer project, I built an Excel-based model to identify potentially fraudulent transactions. I used logical formulas like IF and AND to assign a risk score based on conditions such as high transaction amounts or late night transactions or unusual activity. I then applied conditional formatting to highlight the risk levels and used pivot tables and charts to summarize the data. The end result was a dashboard that helps detect and visualize fraud patterns efficiently
